Workbook

Sheet 取説
A1: 1. エディタの基本構造
A2: 画面下部のタブ（シート）は、「階層（1F/2F）」と「パーツの種類（レイヤー）」ごとに分かれています。 RPGツクールなどのレイヤー機能と同じイメージで、各シートを切り替えながら配置していきます。
A3: シートの方向は上方向が北、下が南、右が東、左が西となっています。分かりやすく罫線で表示されていますが北と南が重なったりするとゲームが重くなる可能性があるので基本的に北と西を使ってください。
A4: 床シート（1F床 / 2F床）： 地面や階段を配置します。場所が限定的な物があります注意してください。
A5: 壁シート（1F壁 / 2F壁）： 東西南北の壁を配置します。
A6: ドアシート（1Fドア / 2Fドア）： 扉を配置します。ドアは２マスで一つのプレハブを使っています。方向に注意してください。
A7: 窓シート（1F窓 / 2F窓）： 窓を配置します。
A8: 家具シート（1F家具 / 2F家具）： 机や小物などを配置します。プレイヤー、敵もここで追加します。
A10: 2. マップの作り方（基本の操作）
A11: マップの配置作業は、すべて「F2」セルから右下のエリアで行います。（A〜C列はシステム用の対応表なので触らないでください）
A12: 1. 配置したい階・種類のシートを開きます。
A13: 2. マス（セル）を選択し、プルダウン（▼）から置きたいパーツの名前を選びます。
... A31: 裏側の数値（10桁のID）とUnityのプレハブが紐づいているため、Excel側だけ名前を変えると表示されなくなります。

Sheet テンプレート
A1: プレハブ名 | B1: 数値 | C1: リスト
C2: {=LEFT(B2:B100 & "0000000000", 10)} -> 0000000000
C3: 0000000000
C4: 0000000000
C5: 0000000000
C6: 0000000000
C7: 0000000000
C8: 0000000000
C9: 0000000000
C10: 0000000000
C11: 0000000000
C12: 0000000000
C13: 0000000000
C14: 0000000000
... C100: 0000000000

Sheet 2F床
A1: プレハブ名 | B1: 数値 | C1: リスト
A2: 床 | B2: 1 | C2: {=LEFT(B2:B100 & "0000000000", 10)} -> 1000000000 | F2: 床 | G2: 床 | H2: 床 | I2: 床 | J2: 床 | K2: 床 | L2: 床 | M2: 床 | N2: 床 | O2: 床 | P2: 床 | Q2: 床 | R2: 床 | S2: 床 | T2: 床 | U2: 床 | V2: 床 | W2: 床 | X2: 床 | Y2: 床 | Z2: 床 | AA2: 床 | AB2: 床 | AC2: 床 | AD2: 床 | AE2: 床 | AF2: 床 | AG2: 床 | AH2: 床 | AI2: 床 | AJ2: 床 | AK2: 床 | AL2: 床 | AM2: 床 | AN2: 床 | AO2: なし
A3: 階段 | B3: 2 | C3: 2000000000 | F3: 床 | G3: 床 | H3: 床 | I3: 床 | J3: 床 | K3: 床 | L3: 床 | M3: 床 | N3: 床 | O3: 床 | P3: 床 | Q3: 床 | R3: 床 | S3: 床 | T3: 床 | U3: 床 | V3: 床 | W3: 床 | X3: 床 | Y3: 床 | Z3: 床 | AA3: 床 | AB3: 床 | AC3: 床 | AD3: 床 | AE3: 床 | AF3: 床 | AG3: 床 | AH3: 床 | AI3: 床 | AJ3: 床 | AK3: 床 | AL3: 床 | AM3: 床 | AN3: 床 | AO3: なし
A4: ２階 | B4: 3 | C4: 3000000000 | F4: 床 | G4: 床 | H4: 床 | I4: 床 | J4: 床 | K4: 床 | L4: 床 | M4: 床 | N4: 床 | O4: 床 | P4: 床 | Q4: 床 | R4: 床 | S4: 床 | T4: 床 | U4: 床 | V4: 床 | W4: 床 | X4: 床 | Y4: 床 | Z4: 床 | AA4: 床 | AB4: 床 | AC4: 床 | AD4: 床 | AE4: 床 | AF4: 床 | AG4: 床 | AH4: 床 | AI4: 床 | AJ4: 床 | AK4: 床 | AL4: 床 | AM4: 床 | AN4: 床 | AO4: なし
A5: 食堂 | B5: 4 | C5: 4000000000 | F5: 床 | G5: 床 | H5: 床 | I5: 床 | J5: 床 | K5: 床 | L5: 床 | M5: 床 | N5: 床 | O5: 床 | P5: 床 | Q5: 床 | R5: 床 | S5: 床 | T5: 床 | U5: 床 | V5: 床 | W5: 床 | X5: 床 | Y5: 床 | Z5: 床 | AA5: 床 | AB5: 床 | AC5: 床 | AD5: 床 | AE5: 床 | AF5: 床 | AG5: 床 | AH5: 床 | AI5: 床 | AJ5: 床 | AK5: 床 | AL5: 床 | AM5: 床 | AN5: 床 | AO5: なし
C6: 0000000000 | F6: 床 | G6: 床 | H6: 床 | I6: 床 | J6: 床 | K6: 床 | L6: 床 | M6: 床 | N6: 床 | O6: 床 | P6: 床 | Q6: 床 | R6: 床 | S6: 床 | T6: 床 | U6: 床 | V6: 床 | W6: 床 | X6: 床 | Y6: 床 | Z6: 床 | AA6: 床 | AB6: 床 | AC6: 床 | AD6: 床 | AE6: 床 | AF6: 床 | AG6: 床 | AH6: 床 | AI6: 床 | AJ6: 床 | AK6: 床 | AL6: 床 | AM6: 床 | AN6: 床 | AO6: なし
C7: 0000000000 | F7: 床 | G7: 床 | H7: 床 | I7: 床 | J7: 床 | K7: 床 | L7: 床 | M7: 床 | N7: 床 | O7: 床 | P7: 床 | Q7: 床 | R7: 床 | S7: 床 | T7: 床 | U7: 床 | V7: 床 | W7: 床 | X7: 床 | Y7: 床 | Z7: 床 | AA7: 床 | AB7: 床 | AC7: 床 | AD7: 床 | AE7: 床 | AF7: 床 | AG7: 床 | AH7: 床 | AI7: 床 | AJ7: 床 | AK7: 床 | AL7: 床 | AM7: 床 | AN7: 床 | AO7: なし
C8: 0000000000 | F8: 床 | G8: 床 | H8: 床 | I8: 床 | J8: 床 | K8: 床 | L8: 床 | M8: 床 | N8: 床 | O8: 床 | P8: 床 | Q8: 床 | R8: 床 | S8: 床 | T8: 床 | U8: 床 | V8: 床 | W8: 床 | X8: 床 | Y8: 床 | Z8: 床 | AA8: 床 | AB8: 床 | AC8: 床 | AD8: 床 | AE8: 床 | AF8: 床 | AG8: 床 | AH8: 床 | AI8: 床 | AJ8: 床 | AK8: 床 | AL8: 床 | AM8: 床 | AN8: 床 | AO8: なし
C9: 0000000000 | F9: 床 | G9: 床 | H9: 床 | I9: 床 | J9: 床 | K9: 床 | L9: 床 | M9: 床 | N9: 床 | O9: 床 | P9: 床 | Q9: 床 | R9: 床 | S9: 床 | T9: 床 | U9: 床 | V9: 床 | W9: 床 | X9: 床 | Y9: 床 | Z9: 床 | AA9: 床 | AB9: 床 | AC9: 床 | AD9: 床 | AE9: 床 | AF9: 床 | AG9: 床 | AH9: 床 | AI9: 床 | AJ9: 床 | AK9: 床 | AL9: 床 | AM9: 床 | AN9: 床 | AO9: なし
C10: 0000000000 | F10: 床 | G10: 床 | H10: 床 | I10: 床 | J10: 床 | K10: 床 | L10: 床 | M10: 床 | N10: 床 | O10: 床 | P10: 床 | Q10: 床 | R10: 床 | S10: 床 | T10: 床 | U10: 床 | V10: 床 | W10: 床 | X10: 床 | Y10: 床 | Z10: 床 | AA10: 床 | AB10: 床 | AC10: 床 | AD10: 床 | AE10: 床 | AF10: 床 | AG10: 床 | AH10: 床 | AI10: 床 | AJ10: 床 | AK10: 床 | AL10: 床 | AM10: 床 | AN10: 床 | AO10: なし
C11: 0000000000 | F11: 床 | G11: 床 | H11: 床 | I11: 床 | J11: 床 | K11: 床 | L11: 床 | M11: 床 | N11: 床 | O11: 床 | P11: 床 | Q11: 床 | R11: 床 | S11: 床 | T11: 床 | U11: 床 | V11: 床 | W11: 床 | X11: 床 | Y11: 床 | Z11: 床 | AA11: 床 | AB11: 床 | AC11: 床 | AD11: 床 | AE11: 床 | AF11: 床 | AG11: 床 | AH11: 床 | AI11: 床 | AJ11: 床 | AK11: 床 | AL11: 床 | AM11: 床 | AN11: 床 | AO11: なし
C12: 0000000000 | F12: 床 | G12: 床 | H12: 床 | I12: 床 | J12: 床 | K12: 床 | L12: 床 | M12: 床 | N12: 床 | O12: 床 | P12: 床 | Q12: 床 | R12: 床 | S12: 床 | T12: 床 | U12: 床 | V12: 床 | W12: 床 | X12: 床 | Y12: 床 | Z12: 床 | AA12: 床 | AB12: 床 | AC12: 床 | AD12: 床 | AE12: 床 | AF12: 床 | AG12: 床 | AH12: 床 | AI12: 床 | AJ12: 床 | AK12: 床 | AL12: 床 | AM12: 床 | AN12: 床 | AO12: なし
C13: 0000000000 | F13: 床 | G13: 床 | H13: 床 | I13: 床 | J13: 床 | K13: 床 | L13: 床 | M13: 床 | N13: 床 | O13: 床 | P13: 床 | Q13: 床 | R13: 床 | S13: 床 | T13: 床 | U13: 床 | V13: 床 | W13: 床 | X13: 床 | Y13: 床 | Z13: 床 | AA13: 床 | AB13: 床 | AC13: 床 | AD13: 床 | AE13: 床 | AF13: 床 | AG13: 床 | AH13: 床 | AI13: 床 | AJ13: 床 | AK13: 床 | AL13: 床 | AM13: 床 | AN13: 床 | AO13: なし
C14: 0000000000 | F14: 床 | G14: 床 | H14: 床 | I14: 床 | J14: 床 | K14: 床 | L14: 床 | M14: 床 | N14: 床 | O14: 床 | P14: 床 | Q14: 床 | R14: 床 | S14: 床 | T14: 床 | U14: 床 | V14: 床 | W14: 床 | X14: 床 | Y14: 床 | Z14: 床 | AA14: 床 | AB14: 床 | AC14: 床 | AD14: 床 | AE14: 床 | AF14: 床 | AG14: 床 | AH14: 床 | AI14: 床 | AJ14: 床 | AK14: 床 | AL14: 床 | AM14: 床 | AN14: 床 | AO14: なし
C15: 0000000000 | F15: 床 | G15: 床 | H15: 床 | I15: 床 | J15: 床 | K15: 床 | L15: 床 | M15: 床 | N15: 床 | O15: 床 | P15: 床 | Q15: 床 | R15: 床 | S15: 床 | T15: 床 | U15: 床 | V15: 床 | W15: 床 | X15: 床 | Y15: 床 | Z15: 床 | AA15: 床 | AB15: 床 | AC15: 床 | AD15: 床 | AE15: 床 | AF15: 床 | AG15: 床 | AH15: 床 | AI15: 床 | AJ15: 床 | AK15: 床 | AL15: 床 | AM15: 床 | AN15: 床 | AO15: なし
C16: 0000000000 | F16: 床 | G16: 床 | H16: 床 | I16: 床 | J16: 床 | K16: 床 | L16: 床 | M16: 床 | N16: 床 | O16: 床 | P16: 床 | Q16: 床 | R16: 床 | S16: 床 | T16: 床 | U16: 床 | V16: 床 | W16: 床 | X16: 床 | Y16: 床 | Z16: 床 | AA16: 床 | AB16: 床 | AC16: 床 | AD16: 床 | AE16: 床 | AF16: 床 | AG16: 床 | AH16: 床 | AI16: 床 | AJ16: 床 | AK16: 床 | AL16: 床 | AM16: 床 | AN16: 床 | AO16: なし
C17: 0000000000 | F17: 床 | G17: 床 | H17: 床 | I17: 床 | J17: 床 | K17: 床 | L17: 床 | M17: 床 | N17: 床 | O17: 床 | P17: 床 | Q17: 床 | R17: 床 | S17: 床 | T17: 床 | U17: 床 | V17: 床 | W17: 床 | X17: 床 | Y17: 床 | Z17: 床 | AA17: 床 | AB17: 床 | AC17: 床 | AD17: 床 | AE17: 床 | AF17: 床 | AG17: 床 | AH17: 床 | AI17: 床 | AJ17: 床 | AK17: 床 | AL17: 床 | AM17: 床 | AN17: 床 | AO17: なし
... C30: 0000000000 | F30: なし | G30: なし | H30: なし | I30: なし | J30: なし | K30: なし | L30: なし | M30: なし | N30: なし | O30: なし | P30: なし | Q30: なし | R30: なし | S30: なし | T30: なし | U30: なし | V30: なし | W30: なし | X30: なし | Y30: なし | Z30: なし | AA30: なし | AB30: なし | AC30: なし | AD30: なし | AE30: なし | AF30: なし | AG30: なし | AH30: なし | AI30: なし | AJ30: なし | AK30: なし | AL30: なし | AM30: なし | AN30: なし | AO30: なし
C31: 0000000000 | F31: なし
C32: 0000000000
C33: 0000000000
C34: 0000000000
C35: 0000000000
C36: 0000000000
C37: 0000000000
C38: 0000000000
C39: 0000000000
C40: 0000000000
C41: 0000000000
C42: 0000000000
C43: 0000000000
... C100: 0000000000

Sheet 2F壁
A1: プレハブ名 | B1: 数値 | C1: リスト
A2: 東壁 | B2: 001 | C2: {=LEFT(B2:B100 & "0000000000", 10)} -> 0010000000 | F2: なし
A3: 西壁 | B3: 002 | C3: 0020000000 | F3: なし | G3: なし | J3: 西壁＋北壁 | K3: 北壁 | L3: 北壁 | M3: 西壁＋北壁 | N3: 北壁 | O3: 北壁 | P3: 西壁＋北壁 | Q3: 北壁 | R3: 西壁 | Z3: 西壁＋北壁 | AA3: 北壁 | AB3: 北壁 | AC3: 北壁 | AD3: 西壁＋北壁 | AE3: 北壁 | AF3: 北壁 | AG3: 北壁 | AH3: 西壁
A4: 南壁 | B4: 003 | C4: 0030000000 | F4: なし | J4: 西壁 | M4: 西壁 | P4: 西壁 | R4: 西壁 | Z4: 西壁 | AD4: なし | AH4: 西壁
A5: 北壁 | B5: 004 | C5: 0040000000 | F5: なし | J5: 西壁 | M5: 西壁 | R5: 西壁 | Z5: 西壁 | AD5: なし | AH5: 西壁
A6: 東壁＋南壁 | B6: 005 | C6: 0050000000 | F6: なし | J6: 西壁 | M6: 西壁 | N6: なし | R6: 西壁 | Z6: 西壁 | AD6: 西壁 | AH6: 西壁
A7: 東壁＋北壁 | B7: 006 | C7: 0060000000 | G7: 西壁＋北壁 | H7: 北壁 | I7: 北壁 | J7: 北壁 | K7: なし | L7: なし | M7: 北壁 | N7: なし | P7: 北壁 | Q7: 北壁 | R7: 北壁 | S7: 北壁 | T7: 北壁 | U7: 北壁 | V7: 北壁 | W7: 北壁 | X7: 北壁 | Y7: 北壁 | Z7: 北壁 | AA7: 北壁 | AD7: 西壁 | AF7: 北壁 | AG7: 北壁 | AH7: 北壁 | AI7: 北壁 | AJ7: 北壁 | AK7: 西壁
A8: 西壁＋南壁 | B8: 007 | C8: 0070000000 | G8: 西壁 | AD8: 西壁 | AK8: 西壁
A9: 西壁＋北壁 | B9: 008 | C9: 0080000000 | G9: 西壁＋北壁 | H9: 北壁 | K9: 西壁 | L9: なし | M9: 北壁 | N9: 北壁 | O9: 北壁 | P9: なし | Q9: なし | R9: 北壁 | S9: 北壁 | T9: 北壁 | U9: 北壁 | V9: 北壁 | W9: 北壁 | X9: 北壁 | Y9: 北壁 | Z9: 北壁 | AA9: 北壁 | AB9: 北壁 | AC9: 北壁 | AD9: 北壁 | AE9: なし | AF9: なし | AG9: 西壁 | AK9: 西壁
A10: なし | C10: 0000000000 | G10: 西壁 | K10: 西壁 | M10: なし | AG10: 西壁＋北壁 | AJ10: 北壁 | AK10: 西壁
C11: 0000000000 | G11: 西壁＋北壁 | H11: 北壁 | I11: 北壁 | J11: 北壁 | K11: 北壁 | L11: 北壁 | M11: 北壁 | N11: 北壁 | O11: 西壁＋北壁 | P11: 北壁 | Q11: 北壁 | R11: 北壁 | S11: 北壁 | T11: 北壁 | U11: 北壁 | V11: 北壁 | W11: 北壁 | X11: 北壁 | Y11: 北壁 | Z11: 北壁 | AA11: 北壁 | AB11: 北壁 | AC11: 西壁＋北壁 | AD11: 北壁 | AE11: なし | AF11: なし | AG11: なし | AJ11: なし | AK11: 西壁
C12: 0000000000 | G12: 西壁 | O12: 西壁 | AC12: 西壁 | AG12: なし | AK12: 西壁
C13: 0000000000 | G13: 西壁 | O13: 西壁 | AC13: 西壁＋北壁 | AD13: 北壁 | AG13: 北壁 | AH13: 北壁 | AI13: 北壁 | AJ13: 北壁 | AK13: 西壁
C14: 0000000000 | G14: 西壁 | O14: 西壁 | AC14: 西壁 | AG14: なし | AK14: 西壁
C15: 0000000000 | G15: 北壁 | H15: 北壁 | I15: 北壁 | J15: 北壁 | K15: 北壁 | L15: 北壁 | M15: 北壁 | N15: 北壁 | O15: 西壁 | AC15: 西壁＋北壁 | AD15: 北壁 | AE15: 北壁 | AF15: 北壁 | AG15: 北壁 | AH15: 北壁 | AI15: 北壁 | AJ15: 北壁
C16: 0000000000 | F16: なし | O16: 西壁 | AC16: 西壁
C17: 0000000000 | F17: なし | O17: 北壁 | P17: 北壁 | Q17: 北壁 | R17: 北壁 | S17: 北壁 | T17: 北壁 | U17: 北壁 | V17: 北壁 | W17: 北壁 | X17: 北壁 | Y17: 北壁 | Z17: 北壁 | AA17: 北壁 | AB17: 北壁
C18: 0000000000 | F18: なし | G18: なし | H18: なし | I18: なし | J18: なし | K18: なし | L18: なし | M18: なし | N18: なし | O18: なし | P18: なし | Q18: なし | R18: なし | S18: なし | T18: なし | U18: なし | V18: なし | W18: なし | X18: なし | Y18: なし | Z18: なし | AA18: なし | AB18: なし | AC18: なし | AD18: なし | AE18: なし | AF18: なし | AG18: なし | AH18: なし | AI18: なし | AJ18: なし | AK18: なし | AL18: なし | AM18: なし | AN18: なし | AO18: なし
C19: 0000000000 | F19: なし | G19: なし | H19: なし | I19: なし | J19: なし | K19: なし | L19: なし | M19: なし | N19: なし | O19: なし | P19: なし | Q19: なし | R19: なし | S19: なし | T19: なし | U19: なし | V19: なし | W19: なし | X19: なし | Y19: なし | Z19: なし | AA19: なし | AB19: なし | AC19: なし | AD19: なし | AE19: なし | AF19: なし | AG19: なし | AH19: なし | AI19: なし | AJ19: なし | AK19: なし | AL19: なし | AM19: なし | AN19: なし | AO19: なし
C20: 0000000000 | F20: なし | G20: なし | H20: なし | I20: なし | J20: なし | K20: なし | L20: なし | M20: なし | N20: なし | O20: なし | P20: なし | Q20: なし | R20: なし | S20: なし | T20: なし | U20: なし | V20: なし | W20: なし | X20: なし | Y20: なし | Z20: なし | AA20: なし | AB20: なし | AC20: なし | AD20: なし | AE20: なし | AF20: なし | AG20: なし | AH20: なし | AI20: なし | AJ20: なし | AK20: なし | AL20: なし | AM20: なし | AN20: なし | AO20: なし
C21: 0000000000 | F21: なし | G21: なし | H21: なし | I21: なし | J21: なし | K21: なし | L21: なし | M21: なし | N21: なし | O21: なし | P21: なし | Q21: なし | R21: なし | S21: なし | T21: なし | U21: なし | V21: なし | W21: なし | X21: なし | Y21: なし | Z21: なし | AA21: なし | AB21: なし | AC21: なし | AD21: なし | AE21: なし | AF21: なし | AG21: なし | AH21: なし | AI21: なし | AJ21: なし | AK21: なし | AL21: なし | AM21: なし | AN21: なし | AO21: なし
C22: 0000000000 | F22: なし | G22: なし | H22: なし | I22: なし | J22: なし | K22: なし | L22: なし | M22: なし | N22: なし | O22: なし | P22: なし | Q22: なし | R22: なし | S22: なし | T22: なし | U22: なし | V22: なし | W22: なし | X22: なし | Y22: なし | Z22: なし | AA22: なし | AB22: なし | AC22: なし | AD22: なし | AE22: なし | AF22: なし | AG22: なし | AH22: なし | AI22: なし | AJ22: なし | AK22: なし | AL22: なし | AM22: なし | AN22: なし | AO22: なし
C23: 0000000000 | F23: なし | G23: なし | H23: なし | I23: なし | J23: なし | K23: なし | L23: なし | M23: なし | N23: なし | O23: なし | P23: なし | Q23: なし | R23: なし | S23: なし | T23: なし | U23: なし | V23: なし | W23: なし | X23: なし | Y23: なし | Z23: なし | AA23: なし | AB23: なし | AC23: なし | AD23: なし | AE23: なし | AF23: なし | AG23: なし | AH23: なし | AI23: なし | AJ23: なし | AK23: なし | AL23: なし | AM23: なし | AN23: なし | AO23: なし
C24: 0000000000 | F24: なし | G24: なし | H24: なし | I24: なし | J24: なし | K24: なし | L24: なし | M24: なし | N24: なし | O24: なし | P24: なし | Q24: なし | R24: なし | S24: なし | T24: なし | U24: なし | V24: なし | W24: なし | X24: なし | Y24: なし | Z24: なし | AA24: なし | AB24: なし | AC24: なし | AD24: なし | AE24: なし | AF24: なし | AG24: なし | AH24: なし | AI24: なし | AJ24: なし | AK24: なし | AL24: なし | AM24: なし | AN24: なし | AO24: なし
C25: 0000000000 | F25: なし | G25: なし | H25: なし | I25: なし | J25: なし | K25: なし | L25: なし | M25: なし | N25: なし | O25: なし | P25: なし | Q25: なし | R25: なし | S25: なし | T25: なし | U25: なし | V25: なし | W25: なし | X25: なし | Y25: なし | Z25: なし | AA25: なし | AB25: なし | AC25: なし | AD25: なし | AE25: なし | AF25: なし | AG25: なし | AH25: なし | AI25: なし | AJ25: なし | AK25: なし | AL25: なし | AM25: なし | AN25: なし | AO25: なし
C26: 0000000000 | F26: なし | G26: なし | H26: なし | I26: なし | J26: なし | K26: なし | L26: なし | M26: なし | N26: なし | O26: なし | P26: なし | Q26: なし | R26: なし | S26: なし | T26: なし | U26: なし | V26: なし | W26: なし | X26: なし | Y26: なし | Z26: なし | AA26: なし | AB26: なし | AC26: なし | AD26: なし | AE26: なし | AF26: なし | AG26: なし | AH26: なし | AI26: なし | AJ26: なし | AK26: なし | AL26: なし | AM26: なし | AN26: なし | AO26: なし
C27: 0000000000 | F27: なし | G27: なし | H27: なし | I27: なし | J27: なし | K27: なし | L27: なし | M27: なし | N27: なし | O27: なし | P27: なし | Q27: なし | R27: なし | S27: なし | T27: なし | U27: なし | V27: なし | W27: なし | X27: なし | Y27: なし | Z27: なし | AA27: なし | AB27: なし | AC27: なし | AD27: なし | AE27: なし | AF27: なし | AG27: なし | AH27: なし | AI27: なし | AJ27: なし | AK27: なし | AL27: なし | AM27: なし | AN27: なし | AO27: なし
C28: 0000000000 | F28: なし | G28: なし | H28: なし | I28: なし | J28: なし | K28: なし | L28: なし | M28: なし | N28: なし | O28: なし | P28: なし | Q28: なし | R28: なし | S28: なし | T28: なし | U28: なし | V28: なし | W28: なし | X28: なし | Y28: なし | Z28: なし | AA28: なし | AB28: なし | AC28: なし | AD28: なし | AE28: なし | AF28: なし | AG28: なし | AH28: なし | AI28: なし | AJ28: なし | AK28: なし | AL28: なし | AM28: なし | AN28: なし | AO28: なし
C29: 0000000000 | F29: なし | G29: なし | H29: なし | I29: なし | J29: なし | K29: なし | L29: なし | M29: なし | N29: なし | O29: なし | P29: なし | Q29: なし | R29: なし | S29: なし | T29: なし | U29: なし | V29: なし | W29: なし | X29: なし | Y29: なし | Z29: なし | AA29: なし | AB29: なし | AC29: なし | AD29: なし | AE29: なし | AF29: なし | AG29: なし | AH29: なし | AI29: なし | AJ29: なし | AK29: なし | AL29: なし | AM29: なし | AN29: なし | AO29: なし
C30: 0000000000 | F30: なし | G30: なし | H30: なし | I30: なし | J30: なし | K30: なし | L30: なし | M30: なし | N30: なし | O30: なし | P30: なし | Q30: なし | R30: なし | S30: なし | T30: なし | U30: なし | V30: なし | W30: なし | X30: なし | Y30: なし | Z30: なし | AA30: なし | AB30: なし | AC30: なし | AD30: なし | AE30: なし | AF30: なし | AG30: なし | AH30: なし | AI30: なし | AJ30: なし | AK30: なし | AL30: なし | AM30: なし | AN30: なし | AO30: なし
C31: 0000000000
C32: 0000000000
C33: 0000000000
C34: 0000000000
C35: 0000000000
C36: 0000000000
C37: 0000000000
C38: 0000000000
C39: 0000000000
C40: 0000000000
...

Sheet 2Fドア
A1: プレハブ名 | B1: 数値 | C1: リスト
A2: 東ドア | B2: 00001 | C2: {=LEFT(B2:B100 & "0000000000", 10)} -> 0000100000
A3: 西ドア | B3: 00002 | C3: 0000200000 | M3: なし
A4: 南ドア | B4: 00003 | C4: 0000300000 | M4: なし | N4: なし | AC4: 東ドア（仮）
A5: 北ドア | B5: 00004 | C5: 0000400000 | M5: なし | O5: 東ドア（仮） | AC5: 東ドア
A6: 東ドア＋南ドア | B6: 00005 | C6: 0000500000 | K6: 南ドア | L6: 南ドア（仮） | N6: 南ドア | O6: 東ドア＋南ドア（仮） | P6: なし | AB6: 南ドア | AC6: 南ドア（仮） | AD6: 南ドア | AE6: 南ドア（仮）
A7: 東ドア＋北ドア | B7: 00006 | C7: 0000600000 | J7: 東ドア（仮） | M7: 東ドア（仮） | Q7: 東ドア（仮） | AF7: 東ドア（仮）
A8: 西ドア＋南ドア | B8: 00007 | C8: 0000700000 | I8: 南ドア | J8: 東ドア＋南ドア（仮） | K8: 南ドア | L8: 南ドア（仮） | M8: 東ドア | O8: なし | P8: 南ドア | Q8: 東ドア＋南ドア（仮） | AE8: 南ドア | AF8: 東ドア＋南ドア（仮）
A9: 西ドア＋北ドア | B9: 00008 | C9: 0000800000 | L9: 東ドア（仮） | AH9: 南ドア | AI9: 南ドア（仮）
A10: 東ドア（仮） | C10: 0000000000 | G10: 南ドア | J10: 東ドア（仮） | L10: 東ドア | AE10: 南ドア | AF10: 南ドア（仮）
A11: 南ドア（仮） | C11: 0000000000 | M11: なし | N11: なし | AF11: 東ドア（仮）
A12: 西ドア（仮） | C12: 0000000000 | N12: なし | AE12: 南ドア | AF12: 東ドア＋南ドア（仮） | AP12: ドアの置き方は
A13: 北ドア（仮） | C13: 0000000000 | N13: なし | AP13: 例 | AQ13: 東のドアを置きたいとき
A14: 東ドア＋南ドア（仮） | B14: 00001 | C14: 0000100000 | AR14: 東→
A15: 東ドア＋北ドア（仮） | C15: 0000000000 | AS15: なし →
A16: 西ドア＋南ドア（仮） | C16: 0000000000 | AS16: 東ドア→
A17: 西ドア＋北ドア（仮） | C17: 0000000000
C18: 0000000000 | AP18: こんな感じで片方はプレハブを置くもう
C19: 0000000000 | AP19: 片方は何も置かない配置にする。
C20: 0000000000
C21: 0000000000 | AP21: ※注意
C22: 0000000000 | AP22: 東は下が東ドアになるように置く
C23: 0000000000 | AP23: 西は上が西ドアになるように置く
C24: 0000000000 | AP24: 南は左が南ドアになるように置く
C25: 0000000000 | AP25: 北は右が北ドアになるように置く
C26: 0000000000 | AP26: 例のなしのところは分かりにくいため
C27: 0000000000 | AP27: それぞれの（仮）をおいてください。
C28: 0000000000
C29: 0000000000
C30: 0000000000
C31: 0000000000
C32: 0000000000
C33: 0000000000
C34: 0000000000
C35: 0000000000
C36: 0000000000
C37: 0000000000
C38: 0000000000
C39: 0000000000
... C100: 0000000000

Sheet 2F窓
A1: プレハブ名 | B1: 数値 | C1: リスト
A2: 東窓 | B2: 0000001 | C2: {=LEFT(B2:B10 & "0000000000", 10)} -> 0000001000 | F2: なし | G2: なし | H2: なし | I2: なし | J2: なし | K2: なし | L2: なし | M2: なし | N2: なし | O2: なし | P2: なし | Q2: なし | R2: なし | S2: なし | T2: なし | U2: なし | V2: なし | W2: なし | X2: なし | Y2: なし | Z2: なし | AA2: なし | AB2: なし | AC2: なし | AD2: なし | AE2: なし | AF2: なし | AG2: なし | AH2: なし | AI2: なし | AJ2: なし | AK2: なし | AL2: なし | AM2: なし | AN2: なし | AO2: なし | AR2: 北
A3: 西窓 | B3: 0000002 | C3: 0000002000 | F3: なし | G3: なし | H3: なし | I3: なし | J3: なし | K3: なし | L3: なし | M3: なし | N3: なし | O3: なし | P3: なし | Q3: なし | R3: なし | S3: なし | T3: なし | U3: なし | V3: なし | W3: なし | X3: なし | Y3: なし | Z3: なし | AA3: なし | AB3: なし | AC3: なし | AD3: なし | AE3: なし | AF3: なし | AG3: なし | AH3: なし | AI3: なし | AJ3: なし | AK3: なし | AL3: なし | AM3: なし | AN3: なし | AO3: なし
A4: 南窓 | B4: 0000003 | C4: 0000003000 | F4: なし | G4: なし | H4: なし | I4: なし | J4: なし | K4: なし | L4: なし | M4: なし | N4: なし | O4: なし | P4: なし | Q4: なし | R4: なし | S4: なし | T4: なし | U4: なし | V4: なし | W4: なし | X4: なし | Y4: なし | Z4: なし | AA4: なし | AB4: なし | AC4: なし | AD4: なし | AE4: なし | AF4: なし | AG4: なし | AH4: なし | AI4: なし | AJ4: なし | AK4: なし | AL4: なし | AM4: なし | AN4: なし | AO4: なし
A5: 北窓 | B5: 0000004 | C5: 0000004000 | F5: なし | G5: なし | H5: なし | I5: なし | J5: なし | K5: なし | L5: なし | M5: なし | N5: なし | O5: なし | P5: なし | Q5: なし | R5: なし | S5: なし | T5: なし | U5: なし | V5: なし | W5: なし | X5: なし | Y5: なし | Z5: なし | AA5: なし | AB5: なし | AC5: なし | AD5: なし | AE5: なし | AF5: なし | AG5: なし | AH5: なし | AI5: なし | AJ5: なし | AK5: なし | AL5: なし | AM5: なし | AN5: なし | AO5: なし
A6: 東窓＋南窓 | B6: 0000005 | C6: 0000005000 | F6: なし | G6: なし | H6: なし | I6: なし | J6: なし | K6: なし | L6: なし | M6: なし | N6: なし | O6: なし | P6: なし | Q6: なし | R6: なし | S6: なし | T6: なし | U6: なし | V6: なし | W6: なし | X6: なし | Y6: なし | Z6: なし | AA6: なし | AB6: なし | AC6: なし | AD6: なし | AE6: なし | AF6: なし | AG6: なし | AH6: なし | AI6: なし | AJ6: なし | AK6: なし | AL6: なし | AM6: なし | AN6: なし | AO6: なし | AP6: 西 | AT6: 東
A7: 東窓＋北窓 | B7: 0000006 | C7: 0000006000 | F7: なし | G7: なし | H7: なし | I7: なし | J7: なし | K7: なし | L7: なし | M7: なし | N7: なし | O7: なし | P7: なし | Q7: なし | R7: なし | S7: なし | T7: なし | U7: なし | V7: なし | W7: なし | X7: なし | Y7: なし | Z7: なし | AA7: なし | AB7: なし | AC7: なし | AD7: なし | AE7: なし | AF7: なし | AG7: なし | AH7: なし | AI7: なし | AJ7: なし | AK7: なし | AL7: なし | AM7: なし | AN7: なし | AO7: なし
A8: 西窓＋南窓 | B8: 0000007 | C8: 0000007000 | F8: なし | G8: なし | H8: なし | I8: なし | J8: なし | K8: なし | L8: なし | M8: なし | N8: なし | O8: なし | P8: なし | Q8: なし | R8: なし | S8: なし | T8: なし | U8: なし | V8: なし | W8: なし | X8: なし | Y8: なし | Z8: なし | AA8: なし | AB8: なし | AC8: なし | AD8: なし | AE8: なし | AF8: なし | AG8: なし | AH8: なし | AI8: なし | AJ8: なし | AK8: なし | AL8: なし | AM8: なし | AN8: なし | AO8: なし
A9: 西窓＋北窓 | B9: 0000008 | C9: 0000008000 | F9: なし | G9: なし | H9: なし | I9: なし | J9: なし | K9: なし | L9: なし | M9: なし | N9: なし | O9: なし | P9: なし | Q9: なし | R9: なし | S9: なし | T9: なし | U9: なし | V9: なし | W9: なし | X9: なし | Y9: なし | Z9: なし | AA9: なし | AB9: なし | AC9: なし | AD9: なし | AE9: なし | AF9: なし | AG9: なし | AH9: なし | AI9: なし | AJ9: なし | AK9: なし | AL9: なし | AM9: なし | AN9: なし | AO9: なし
C10: 0000000000 | F10: なし | G10: なし | H10: なし | I10: なし | J10: なし | K10: なし | L10: なし | M10: なし | N10: なし | O10: なし | P10: なし | Q10: なし | R10: なし | S10: なし | T10: なし | U10: なし | V10: なし | W10: なし | X10: なし | Y10: なし | Z10: なし | AA10: なし | AB10: なし | AC10: なし | AD10: なし | AE10: なし | AF10: なし | AG10: なし | AH10: なし | AI10: なし | AJ10: なし | AK10: なし | AL10: なし | AM10: なし | AN10: なし | AO10: なし | AR10: 南
F11: なし | G11: なし | H11: なし | I11: なし | J11: なし | K11: なし | L11: なし | M11: なし | N11: なし | O11: なし | P11: なし | Q11: なし | Z11: 北窓 | AA11: なし | AB11: なし | AC11: なし | AD11: なし | AE11: なし | AF11: なし | AG11: なし | AH11: なし | AI11: なし | AJ11: なし | AK11: なし | AL11: なし | AM11: なし | AN11: なし | AO11: なし
F12: なし | G12: なし | H12: なし | I12: なし | J12: なし | K12: なし | L12: なし | M12: なし | N12: なし | O12: なし | P12: なし | Q12: なし | R12: なし | S12: なし | T12: なし | U12: なし | V12: なし | W12: なし | X12: なし | Y12: なし | Z12: なし | AA12: なし | AB12: なし | AC12: なし | AD12: なし | AE12: なし | AF12: なし | AG12: なし | AH12: なし | AI12: なし | AJ12: なし | AK12: なし | AL12: なし | AM12: なし | AN12: なし | AO12: なし
F13: なし | G13: なし | H13: なし | I13: なし | J13: なし | K13: なし | L13: なし | M13: なし | N13: なし | O13: なし | P13: なし | Q13: なし | R13: なし | S13: なし | T13: なし | U13: なし | V13: なし | W13: なし | X13: なし | Y13: なし | Z13: なし | AA13: なし | AB13: なし | AC13: なし | AD13: なし | AE13: なし | AF13: なし | AG13: なし | AH13: なし | AI13: なし | AJ13: なし | AK13: なし | AL13: なし | AM13: なし | AN13: なし | AO13: なし
F14: なし | G14: なし | H14: なし | I14: なし | J14: なし | K14: なし | L14: なし | M14: なし | N14: なし | O14: なし | P14: なし | Q14: なし | R14: なし | S14: なし | T14: なし | U14: なし | V14: なし | W14: なし | X14: なし | Y14: なし | Z14: なし | AA14: なし | AB14: なし | AC14: なし | AD14: なし | AE14: なし | AF14: なし | AG14: なし | AH14: なし | AI14: なし | AJ14: なし | AK14: なし | AL14: なし | AM14: なし | AN14: なし | AO14: なし
F15: なし | G15: なし | H15: なし | I15: なし | J15: なし | K15: なし | L15: なし | M15: なし | N15: なし | O15: なし | P15: なし | Q15: なし | R15: なし | S15: なし | T15: なし | U15: なし | V15: なし | W15: なし | X15: なし | Y15: なし | Z15: なし | AA15: なし | AB15: なし | AC15: なし | AD15: なし | AE15: なし | AF15: なし | AG15: なし | AH15: なし | AI15: なし | AJ15: なし | AK15: なし | AL15: なし | AM15: なし | AN15: なし | AO15: なし
F16: なし | G16: なし | H16: なし | I16: なし | J16: なし | K16: なし | L16: なし | M16: なし | N16: なし | O16: なし | P16: なし | Q16: なし | R16: なし | S16: なし | T16: なし | U16: なし | V16: なし | W16: なし | X16: なし | Y16: なし | Z16: なし | AA16: なし | AB16: なし | AC16: なし | AD16: なし | AE16: なし | AF16: なし | AG16: なし | AH16: なし | AI16: なし | AJ16: なし | AK16: なし | AL16: なし | AM16: なし | AN16: なし | AO16: なし
F17: なし | G17: なし | H17: なし | I17: なし | J17: なし | K17: なし | L17: なし | M17: なし | N17: なし | O17: なし | P17: なし | Q17: なし | R17: なし | S17: なし | T17: なし | U17: なし | V17: なし | W17: なし | X17: なし | Y17: なし | Z17: なし | AA17: なし | AB17: なし | AC17: なし | AD17: なし | AE17: なし | AF17: なし | AG17: なし | AH17: なし | AI17: なし | AJ17: なし | AK17: なし | AL17: なし | AM17: なし | AN17: なし | AO17: なし
F18: なし | G18: なし | H18: なし | I18: なし | J18: なし | K18: なし | L18: なし | M18: なし | N18: なし | O18: なし | P18: なし | Q18: なし | R18: なし | S18: なし | T18: なし | U18: なし | V18: なし | W18: なし | X18: なし | Y18: なし | Z18: なし | AA18: なし | AB18: なし | AC18: なし | AD18: なし | AE18: なし | AF18: なし | AG18: なし | AH18: なし | AI18: なし | AJ18: なし | AK18: なし | AL18: なし | AM18: なし | AN18: なし | AO18: なし
F19: なし | G19: なし | H19: なし | I19: なし | J19: なし | K19: なし | L19: なし | M19: なし | N19: なし | O19: なし | P19: なし | Q19: なし | R19: なし | S19: なし | T19: なし | U19: なし | V19: なし | W19: なし | X19: なし | Y19: なし | Z19: なし | AA19: なし | AB19: なし | AC19: なし | AD19: なし | AE19: なし | AF19: なし | AG19: なし | AH19: なし | AI19: なし | AJ19: なし | AK19: なし | AL19: なし | AM19: なし | AN19: なし | AO19: なし
F20: なし | G20: なし | H20: なし | I20: なし | J20: なし | K20: なし | L20: なし | M20: なし | N20: なし | O20: なし | P20: なし | Q20: なし | R20: なし | S20: なし | T20: なし | U20: なし | V20: なし | W20: なし | X20: なし | Y20: なし | Z20: なし | AA20: なし | AB20: なし | AC20: なし | AD20: なし | AE20: なし | AF20: なし | AG20: なし | AH20: なし | AI20: なし | AJ20: なし | AK20: なし | AL20: なし | AM20: なし | AN20: なし | AO20: なし
F21: なし | G21: なし | H21: なし | I21: なし | J21: なし | K21: なし | L21: なし | M21: なし | N21: なし | O21: なし | P21: なし | Q21: なし | R21: なし | S21: なし | T21: なし | U21: なし | V21: なし | W21: なし | X21: なし | Y21: なし | Z21: なし | AA21: なし | AB21: なし | AC21: なし | AD21: なし | AE21: なし | AF21: なし | AG21: なし | AH21: なし | AI21: なし | AJ21: なし | AK21: なし | AL21: なし | AM21: なし | AN21: なし | AO21: なし
F22: なし | G22: なし | H22: なし | I22: なし | J22: なし | K22: なし | L22: なし | M22: なし | N22: なし | O22: なし | P22: なし | Q22: なし | R22: なし | S22: なし | T22: なし | U22: なし | V22: なし | W22: なし | X22: なし | Y22: なし | Z22: なし | AA22: なし | AB22: なし | AC22: なし | AD22: なし | AE22: なし | AF22: なし | AG22: なし | AH22: なし | AI22: なし | AJ22: なし | AK22: なし | AL22: なし | AM22: なし | AN22: なし | AO22: なし
F23: なし | G23: なし | H23: なし | I23: なし | J23: なし | K23: なし | L23: なし | M23: なし | N23: なし | O23: なし | P23: なし | Q23: なし | R23: なし | S23: なし | T23: なし | U23: なし | V23: なし | W23: なし | X23: なし | Y23: なし | Z23: なし | AA23: なし | AB23: なし | AC23: なし | AD23: なし | AE23: なし | AF23: なし | AG23: なし | AH23: なし | AI23: なし | AJ23: なし | AK23: なし | AL23: なし | AM23: なし | AN23: なし | AO23: なし
... F30: なし | G30: なし | H30: なし | I30: なし | J30: なし | K30: なし | L30: なし | M30: なし | N30: なし | O30: なし | P30: なし | Q30: なし | R30: なし | S30: なし | T30: なし | U30: なし | V30: なし | W30: なし | X30: なし | Y30: なし | Z30: なし | AA30: なし | AB30: なし | AC30: なし | AD30: なし | AE30: なし | AF30: なし | AG30: なし | AH30: なし | AI30: なし | AJ30: なし | AK30: なし | AL30: なし | AM30: なし | AN30: なし | AO30: なし

Sheet 2F家具
A1: プレハブ名 | B1: 数値 | C1: リスト
C2: {=LEFT(B2:B100 & "0000000000", 10)} -> 0000000000
C3: 0000000000
C4: 0000000000
C5: 0000000000
C6: 0000000000
C7: 0000000000
C8: 0000000000
C9: 0000000000
C10: 0000000000
C11: 0000000000
C12: 0000000000
C13: 0000000000
C14: 0000000000
... C100: 0000000000

Sheet 1F床
A1: プレハブ名 | B1: 数値 | C1: リスト
A2: 床 | B2: 1 | C2: {=LEFT(B2:B100 & "0000000000", 10)} -> 1000000000 | F2: 床 | G2: 床 | H2: 床 | I2: 床 | J2: 床 | K2: 床 | L2: 床 | M2: 床 | N2: 床 | O2: 床 | P2: 床 | Q2: 床 | R2: 床 | S2: 床 | T2: 床 | U2: 床 | V2: 床 | W2: 床 | X2: 床 | Y2: 床 | Z2: 床 | AA2: 床 | AB2: 床 | AC2: 床 | AD2: 床 | AE2: 床 | AF2: 床 | AG2: 床 | AH2: 床 | AI2: 床 | AJ2: 床 | AK2: 床 | AL2: 床 | AM2: 床 | AN2: 床 | AO2: なし
A3: 階段 | B3: 2 | C3: 2000000000 | F3: 床 | G3: 床 | H3: 床 | I3: 床 | J3: 床 | K3: 床 | L3: 床 | M3: 床 | N3: 床 | O3: 床 | P3: 床 | Q3: 床 | R3: 床 | S3: 床 | T3: 床 | U3: 床 | V3: 床 | W3: 床 | X3: 床 | Y3: 床 | Z3: 床 | AA3: 床 | AB3: 床 | AC3: 床 | AD3: 床 | AE3: 床 | AF3: 床 | AG3: 床 | AH3: 床 | AI3: 床 | AJ3: 床 | AK3: 床 | AL3: 床 | AM3: 床 | AN3: 床 | AO3: なし
A4: ２階 | B4: 3 | C4: 3000000000 | F4: 床 | G4: 床 | H4: 床 | I4: 床 | J4: 床 | K4: 床 | L4: 床 | M4: 床 | N4: 床 | O4: 床 | P4: 床 | Q4: 床 | R4: 床 | S4: 床 | T4: 床 | U4: 床 | V4: 床 | W4: 床 | X4: 床 | Y4: 床 | Z4: 床 | AA4: 床 | AB4: 床 | AC4: 床 | AD4: 床 | AE4: 床 | AF4: 床 | AG4: 床 | AH4: 床 | AI4: 床 | AJ4: 床 | AK4: 床 | AL4: 床 | AM4: 床 | AN4: 床 | AO4: なし
A5: 食堂 | B5: 4 | C5: 4000000000 | F5: 床 | G5: 床 | H5: 床 | I5: 床 | J5: 床 | K5: 床 | L5: 床 | M5: 床 | N5: 床 | O5: 床 | P5: 床 | Q5: 床 | R5: 床 | S5: 床 | T5: 床 | U5: 床 | V5: 床 | W5: 床 | X5: 床 | Y5: 床 | Z5: 床 | AA5: 床 | AB5: 床 | AC5: 床 | AD5: 床 | AE5: 床 | AF5: 床 | AG5: 床 | AH5: 床 | AI5: 床 | AJ5: 床 | AK5: 床 | AL5: 床 | AM5: 床 | AN5: 床 | AO5: なし
C6: 0000000000 | F6: 床 | G6: 床 | H6: 床 | I6: 床 | J6: 床 | K6: 床 | L6: 床 | M6: 床 | N6: 床 | O6: 床 | P6: 床 | Q6: 床 | R6: 床 | S6: 床 | T6: 床 | U6: 床 | V6: 床 | W6: 床 | X6: 床 | Y6: 床 | Z6: 床 | AA6: 床 | AB6: 床 | AC6: 床 | AD6: 床 | AE6: 床 | AF6: 床 | AG6: 床 | AH6: 床 | AI6: 床 | AJ6: 床 | AK6: 床 | AL6: 床 | AM6: 床 | AN6: 床 | AO6: なし
C7: 0000000000 | F7: 床 | G7: 床 | H7: 床 | I7: 床 | J7: 床 | K7: 床 | L7: 床 | M7: 床 | N7: 床 | O7: 床 | P7: 床 | Q7: 床 | R7: 床 | S7: 床 | T7: 床 | U7: 床 | V7: 床 | W7: 床 | X7: 床 | Y7: 床 | Z7: 床 | AA7: 床 | AB7: 床 | AC7: 床 | AD7: 床 | AE7: 床 | AF7: 床 | AG7: 床 | AH7: 床 | AI7: 床 | AJ7: 床 | AK7: 床 | AL7: 床 | AM7: 床 | AN7: 床 | AO7: なし
C8: 0000000000 | F8: 床 | G8: 床 | H8: 床 | I8: 床 | J8: 床 | K8: 床 | L8: 床 | M8: 床 | N8: 床 | O8: 床 | P8: 床 | Q8: 床 | R8: 床 | S8: 床 | T8: 床 | U8: 床 | V8: 床 | W8: 床 | X8: 床 | Y8: 床 | Z8: 床 | AA8: 床 | AB8: 床 | AC8: 床 | AD8: 床 | AE8: 床 | AF8: 床 | AG8: 床 | AH8: 床 | AI8: 床 | AJ8: 床 | AK8: 床 | AL8: 床 | AM8: 床 | AN8: 床 | AO8: なし
C9: 0000000000 | F9: 床 | G9: 床 | H9: 床 | I9: 床 | J9: 床 | K9: 床 | L9: 床 | M9: 床 | N9: 床 | O9: 床 | P9: 床 | Q9: 床 | R9: 床 | S9: 床 | T9: 床 | U9: 床 | V9: 床 | W9: 床 | X9: 床 | Y9: 床 | Z9: 床 | AA9: 床 | AB9: 床 | AC9: 床 | AD9: 床 | AE9: 床 | AF9: 床 | AG9: 床 | AH9: 床 | AI9: 床 | AJ9: 床 | AK9: 床 | AL9: 床 | AM9: 床 | AN9: 床 | AO9: なし
C10: 0000000000 | F10: 床 | G10: 床 | H10: 床 | I10: 床 | J10: 床 | K10: 床 | L10: 床 | M10: 床 | N10: 床 | O10: 床 | P10: 床 | Q10: 床 | R10: 床 | S10: 床 | T10: 床 | U10: 床 | V10: 床 | W10: 床 | X10: 床 | Y10: 床 | Z10: 床 | AA10: 床 | AB10: 床 | AC10: 床 | AD10: 床 | AE10: 床 | AF10: 床 | AG10: 床 | AH10: 床 | AI10: 床 | AJ10: 床 | AK10: 床 | AL10: 床 | AM10: 床 | AN10: 床 | AO10: なし
C11: 0000000000 | F11: 床 | G11: 床 | H11: 床 | I11: 床 | J11: 床 | K11: 床 | L11: 床 | M11: 床 | N11: 床 | O11: 床 | P11: 床 | Q11: 床 | R11: 床 | S11: 床 | T11: 床 | U11: 階段 | V11: 階段 | W11: 床 | X11: 床 | Y11: 床 | Z11: 床 | AA11: 床 | AB11: 床 | AC11: 床 | AD11: 床 | AE11: 床 | AF11: 床 | AG11: 床 | AH11: 床 | AI11: 床 | AJ11: 床 | AK11: 床 | AL11: 床 | AM11: 床 | AN11: 床 | AO11: なし
C12: 0000000000 | F12: 床 | G12: 床 | H12: 床 | I12: 床 | J12: 床 | K12: 床 | L12: 床 | M12: 床 | N12: 床 | O12: 床 | P12: 床 | Q12: 床 | R12: 床 | S12: 床 | T12: 床 | U12: 階段 | V12: 階段 | W12: 床 | X12: 床 | Y12: 床 | Z12: 床 | AA12: 床 | AB12: 床 | AC12: 床 | AD12: 床 | AE12: 床 | AF12: 床 | AG12: 床 | AH12: 床 | AI12: 床 | AJ12: 床 | AK12: 床 | AL12: 床 | AM12: 床 | AN12: 床 | AO12: なし
C13: 0000000000 | F13: 床 | G13: 床 | H13: 床 | I13: 床 | J13: 床 | K13: 床 | L13: 床 | M13: 床 | N13: 床 | O13: 床 | P13: 床 | Q13: 床 | R13: 床 | S13: 床 | T13: 床 | U13: 床 | V13: 床 | W13: 床 | X13: 床 | Y13: 床 | Z13: 床 | AA13: 床 | AB13: 床 | AC13: 床 | AD13: 床 | AE13: 床 | AF13: 床 | AG13: 床 | AH13: 床 | AI13: 床 | AJ13: 床 | AK13: 床 | AL13: 床 | AM13: 床 | AN13: 床 | AO13: なし
C14: 0000000000 | F14: 床 | G14: 床 | H14: 床 | I14: 床 | J14: 床 | K14: 床 | L14: 床 | M14: 床 | N14: 床 | O14: 床 | P14: 床 | Q14: 床 | R14: 床 | S14: 床 | T14: 床 | U14: 床 | V14: 床 | W14: 床 | X14: 床 | Y14: 床 | Z14: 床 | AA14: 床 | AB14: 床 | AC14: 床 | AD14: 床 | AE14: 床 | AF14: 床 | AG14: 床 | AH14: 床 | AI14: 床 | AJ14: 床 | AK14: 床 | AL14: 床 | AM14: 床 | AN14: 床 | AO14: なし
C15: 0000000000 | F15: 床 | G15: 床 | H15: 床 | I15: 床 | J15: 床 | K15: 床 | L15: 床 | M15: 床 | N15: 床 | O15: 床 | P15: 床 | Q15: 床 | R15: 床 | S15: 床 | T15: 床 | U15: 床 | V15: 床 | W15: 床 | X15: 床 | Y15: 床 | Z15: 床 | AA15: 床 | AB15: 床 | AC15: 床 | AD15: 床 | AE15: 床 | AF15: 床 | AG15: 床 | AH15: 床 | AI15: 床 | AJ15: 床 | AK15: 床 | AL15: 床 | AM15: 床 | AN15: 床 | AO15: なし
C16: 0000000000 | F16: 床 | G16: 床 | H16: 床 | I16: 床 | J16: 床 | K16: 床 | L16: 床 | M16: 床 | N16: 床 | O16: 床 | P16: 床 | Q16: 床 | R16: 床 | S16: 床 | T16: 床 | U16: 床 | V16: 床 | W16: 床 | X16: 床 | Y16: 床 | Z16: 床 | AA16: 床 | AB16: 床 | AC16: 床 | AD16: 床 | AE16: 床 | AF16: 床 | AG16: 床 | AH16: 床 | AI16: 床 | AJ16: 床 | AK16: 床 | AL16: 床 | AM16: 床 | AN16: 床 | AO16: なし
C17: 0000000000 | F17: 床 | G17: 床 | H17: 床 | I17: 床 | J17: 床 | K17: 床 | L17: 床 | M17: 床 | N17: 床 | O17: 床 | P17: 床 | Q17: 床 | R17: 床 | S17: 床 | T17: 床 | U17: 床 | V17: 床 | W17: 床 | X17: 床 | Y17: 床 | Z17: 床 | AA17: 床 | AB17: 床 | AC17: 床 | AD17: 床 | AE17: 床 | AF17: 床 | AG17: 床 | AH17: 床 | AI17: 床 | AJ17: 床 | AK17: 床 | AL17: 床 | AM17: 床 | AN17: 床 | AO17: なし
... C30: 0000000000 | F30: なし | G30: なし | H30: なし | I30: なし | J30: なし | K30: なし | L30: なし | M30: なし | N30: なし | O30: なし | P30: なし | Q30: なし | R30: なし | S30: なし | T30: なし | U30: なし | V30: なし | W30: なし | X30: なし | Y30: なし | Z30: なし | AA30: なし | AB30: なし | AC30: なし | AD30: なし | AE30: なし | AF30: なし | AG30: なし | AH30: なし | AI30: なし | AJ30: なし | AK30: なし | AL30: なし | AM30: なし | AN30: なし | AO30: なし
C31: 0000000000 | F31: なし
C32: 0000000000
C33: 0000000000
C34: 0000000000
C35: 0000000000
C36: 0000000000
C37: 0000000000
C38: 0000000000
C39: 0000000000
C40: 0000000000
C41: 0000000000
C42: 0000000000
C43: 0000000000
... C100: 0000000000

Sheet 1F壁
A1: プレハブ名 | B1: 数値 | C1: リスト
A2: 東壁 | B2: 001 | C2: {=LEFT(B2:B100 & "0000000000", 10)} -> 0010000000 | F2: なし
A3: 西壁 | B3: 002 | C3: 0020000000 | F3: なし | G3: なし | J3: 西壁＋北壁 | K3: 北壁 | L3: 北壁 | M3: 北壁 | N3: 西壁＋北壁 | O3: 北壁 | P3: 北壁 | Q3: 北壁 | R3: 西壁 | Z3: 西壁＋北壁 | AA3: 北壁 | AB3: 北壁 | AC3: 北壁 | AD3: 西壁＋北壁 | AE3: 北壁 | AF3: 北壁 | AG3: 北壁 | AH3: 西壁
A4: 南壁 | B4: 003 | C4: 0030000000 | F4: なし | J4: 西壁 | R4: 西壁 | Z4: 西壁 | AD4: 西壁 | AH4: 西壁
A5: 北壁 | B5: 004 | C5: 0040000000 | F5: なし | J5: 西壁 | R5: 西壁 | Z5: 西壁 | AD5: 西壁 | AH5: 西壁
A6: 東壁＋南壁 | B6: 005 | C6: 0050000000 | F6: なし | J6: 西壁 | N6: 西壁 | R6: 西壁 | Z6: 西壁 | AD6: 西壁 | AH6: 西壁
A7: 東壁＋北壁 | B7: 006 | C7: 0060000000 | G7: 西壁＋北壁 | H7: 北壁 | I7: 北壁 | J7: 北壁 | K7: 北壁 | L7: 北壁 | M7: 北壁 | N7: 北壁 | Q7: 北壁 | R7: 北壁 | S7: 北壁 | T7: 北壁 | U7: 北壁 | V7: 北壁 | W7: 北壁 | X7: 北壁 | Y7: 北壁 | Z7: 北壁 | AA7: 北壁 | AF7: 北壁 | AG7: 北壁 | AH7: 北壁 | AI7: 北壁 | AJ7: 北壁 | AK7: 西壁
A8: 西壁＋南壁 | B8: 007 | C8: 0070000000 | G8: 西壁 | AK8: 西壁
A9: 西壁＋北壁 | B9: 008 | C9: 0080000000 | G9: 西壁 | K9: 北壁 | L9: 北壁 | M9: 西壁＋北壁 | N9: 北壁 | O9: なし | P9: なし | Q9: 北壁 | R9: 北壁 | S9: 北壁 | T9: 北壁 | U9: 北壁 | V9: 北壁 | W9: 北壁 | X9: 北壁 | Y9: 北壁 | Z9: なし | AA9: なし | AB9: 北壁 | AC9: 北壁 | AD9: 北壁 | AE9: 北壁 | AF9: 北壁 | AK9: 西壁
A10: なし | C10: 0000000000 | G10: 西壁 | M10: 西壁 | AK10: 西壁
C11: 0000000000 | G11: 西壁 | I11: 北壁 | J11: 北壁 | K11: 北壁 | L11: 北壁 | M11: 北壁 | N11: 東壁＋北壁 | AC11: 西壁＋北壁 | AD11: 北壁 | AE11: 北壁 | AF11: 北壁 | AG11: 西壁＋北壁 | AJ11: 北壁 | AK11: 西壁
C12: 0000000000 | G12: 西壁 | AG12: 西壁 | AK12: 西壁
C13: 0000000000 | G13: 西壁 | AG13: 西壁 | AK13: 西壁
C14: 0000000000 | G14: 西壁 | O14: 西壁 | AC14: 西壁 | AG14: 西壁 | AK14: 西壁
C15: 0000000000 | G15: 北壁 | H15: 北壁 | I15: 北壁 | J15: 北壁 | K15: 北壁 | L15: 北壁 | M15: 北壁 | N15: 北壁 | O15: 西壁 | AC15: 西壁＋北壁 | AD15: 北壁 | AE15: 北壁 | AF15: 北壁 | AG15: 北壁 | AH15: 北壁 | AI15: 北壁 | AJ15: 北壁
C16: 0000000000 | F16: なし | O16: 西壁 | AC16: 西壁
C17: 0000000000 | F17: なし | O17: 北壁 | P17: 北壁 | Q17: 北壁 | R17: 北壁 | S17: 北壁 | T17: 北壁 | U17: 北壁 | V17: 北壁 | W17: 北壁 | X17: 北壁 | Y17: 北壁 | Z17: 北壁 | AA17: 北壁 | AB17: 北壁
C18: 0000000000 | F18: なし | G18: なし | H18: なし | I18: なし | J18: なし | K18: なし | L18: なし | M18: なし | N18: なし | O18: なし | P18: なし | Q18: なし | R18: なし | S18: なし | T18: なし | U18: なし | V18: なし | W18: なし | X18: なし | Y18: なし | Z18: なし | AA18: なし | AB18: なし | AC18: なし | AD18: なし | AE18: なし | AF18: なし | AG18: なし | AH18: なし | AI18: なし | AJ18: なし | AK18: なし | AL18: なし | AM18: なし | AN18: なし | AO18: なし
C19: 0000000000 | F19: なし | G19: なし | H19: なし | I19: なし | J19: なし | K19: なし | L19: なし | M19: なし | N19: なし | O19: なし | P19: なし | Q19: なし | R19: なし | S19: なし | T19: なし | U19: なし | V19: なし | W19: なし | X19: なし | Y19: なし | Z19: なし | AA19: なし | AB19: なし | AC19: なし | AD19: なし | AE19: なし | AF19: なし | AG19: なし | AH19: なし | AI19: なし | AJ19: なし | AK19: なし | AL19: なし | AM19: なし | AN19: なし | AO19: なし
C20: 0000000000 | F20: なし | G20: なし | H20: なし | I20: なし | J20: なし | K20: なし | L20: なし | M20: なし | N20: なし | O20: なし | P20: なし | Q20: なし | R20: なし | S20: なし | T20: なし | U20: なし | V20: なし | W20: なし | X20: なし | Y20: なし | Z20: なし | AA20: なし | AB20: なし | AC20: なし | AD20: なし | AE20: なし | AF20: なし | AG20: なし | AH20: なし | AI20: なし | AJ20: なし | AK20: なし | AL20: なし | AM20: なし | AN20: なし | AO20: なし
C21: 0000000000 | F21: なし | G21: なし | H21: なし | I21: なし | J21: なし | K21: なし | L21: なし | M21: なし | N21: なし | O21: なし | P21: なし | Q21: なし | R21: なし | S21: なし | T21: なし | U21: なし | V21: なし | W21: なし | X21: なし | Y21: なし | Z21: なし | AA21: なし | AB21: なし | AC21: なし | AD21: なし | AE21: なし | AF21: なし | AG21: なし | AH21: なし | AI21: なし | AJ21: なし | AK21: なし | AL21: なし | AM21: なし | AN21: なし | AO21: なし
C22: 0000000000 | F22: なし | G22: なし | H22: なし | I22: なし | J22: なし | K22: なし | L22: なし | M22: なし | N22: なし | O22: なし | P22: なし | Q22: なし | R22: なし | S22: なし | T22: なし | U22: なし | V22: なし | W22: なし | X22: なし | Y22: なし | Z22: なし | AA22: なし | AB22: なし | AC22: なし | AD22: なし | AE22: なし | AF22: なし | AG22: なし | AH22: なし | AI22: なし | AJ22: なし | AK22: なし | AL22: なし | AM22: なし | AN22: なし | AO22: なし
C23: 0000000000 | F23: なし | G23: なし | H23: なし | I23: なし | J23: なし | K23: なし | L23: なし | M23: なし | N23: なし | O23: なし | P23: なし | Q23: なし | R23: なし | S23: なし | T23: なし | U23: なし | V23: なし | W23: なし | X23: なし | Y23: なし | Z23: なし | AA23: なし | AB23: なし | AC23: なし | AD23: なし | AE23: なし | AF23: なし | AG23: なし | AH23: なし | AI23: なし | AJ23: なし | AK23: なし | AL23: なし | AM23: なし | AN23: なし | AO23: なし
C24: 0000000000 | F24: なし | G24: なし | H24: なし | I24: なし | J24: なし | K24: なし | L24: なし | M24: なし | N24: なし | O24: なし | P24: なし | Q24: なし | R24: なし | S24: なし | T24: なし | U24: なし | V24: なし | W24: なし | X24: なし | Y24: なし | Z24: なし | AA24: なし | AB24: なし | AC24: なし | AD24: なし | AE24: なし | AF24: なし | AG24: なし | AH24: なし | AI24: なし | AJ24: なし | AK24: なし | AL24: なし | AM24: なし | AN24: なし | AO24: なし
C25: 0000000000 | F25: なし | G25: なし | H25: なし | I25: なし | J25: なし | K25: なし | L25: なし | M25: なし | N25: なし | O25: なし | P25: なし | Q25: なし | R25: なし | S25: なし | T25: なし | U25: なし | V25: なし | W25: なし | X25: なし | Y25: なし | Z25: なし | AA25: なし | AB25: なし | AC25: なし | AD25: なし | AE25: なし | AF25: なし | AG25: なし | AH25: なし | AI25: なし | AJ25: なし | AK25: なし | AL25: なし | AM25: なし | AN25: なし | AO25: なし
C26: 0000000000 | F26: なし | G26: なし | H26: なし | I26: なし | J26: なし | K26: なし | L26: なし | M26: なし | N26: なし | O26: なし | P26: なし | Q26: なし | R26: なし | S26: なし | T26: なし | U26: なし | V26: なし | W26: なし | X26: なし | Y26: なし | Z26: なし | AA26: なし | AB26: なし | AC26: なし | AD26: なし | AE26: なし | AF26: なし | AG26: なし | AH26: なし | AI26: なし | AJ26: なし | AK26: なし | AL26: なし | AM26: なし | AN26: なし | AO26: なし
C27: 0000000000 | F27: なし | G27: なし | H27: なし | I27: なし | J27: なし | K27: なし | L27: なし | M27: なし | N27: なし | O27: なし | P27: なし | Q27: なし | R27: なし | S27: なし | T27: なし | U27: なし | V27: なし | W27: なし | X27: なし | Y27: なし | Z27: なし | AA27: なし | AB27: なし | AC27: なし | AD27: なし | AE27: なし | AF27: なし | AG27: なし | AH27: なし | AI27: なし | AJ27: なし | AK27: なし | AL27: なし | AM27: なし | AN27: なし | AO27: なし
C28: 0000000000 | F28: なし | G28: なし | H28: なし | I28: なし | J28: なし | K28: なし | L28: なし | M28: なし | N28: なし | O28: なし | P28: なし | Q28: なし | R28: なし | S28: なし | T28: なし | U28: なし | V28: なし | W28: なし | X28: なし | Y28: なし | Z28: なし | AA28: なし | AB28: なし | AC28: なし | AD28: なし | AE28: なし | AF28: なし | AG28: なし | AH28: なし | AI28: なし | AJ28: なし | AK28: なし | AL28: なし | AM28: なし | AN28: なし | AO28: なし
C29: 0000000000 | F29: なし | G29: なし | H29: なし | I29: なし | J29: なし | K29: なし | L29: なし | M29: なし | N29: なし | O29: なし | P29: なし | Q29: なし | R29: なし | S29: なし | T29: なし | U29: なし | V29: なし | W29: なし | X29: なし | Y29: なし | Z29: なし | AA29: なし | AB29: なし | AC29: なし | AD29: なし | AE29: なし | AF29: なし | AG29: なし | AH29: なし | AI29: なし | AJ29: なし | AK29: なし | AL29: なし | AM29: なし | AN29: なし | AO29: なし
C30: 0000000000 | F30: なし | G30: なし | H30: なし | I30: なし | J30: なし | K30: なし | L30: なし | M30: なし | N30: なし | O30: なし | P30: なし | Q30: なし | R30: なし | S30: なし | T30: なし | U30: なし | V30: なし | W30: なし | X30: なし | Y30: なし | Z30: なし | AA30: なし | AB30: なし | AC30: なし | AD30: なし | AE30: なし | AF30: なし | AG30: なし | AH30: なし | AI30: なし | AJ30: なし | AK30: なし | AL30: なし | AM30: なし | AN30: なし | AO30: なし
C31: 0000000000
C32: 0000000000
C33: 0000000000
C34: 0000000000
C35: 0000000000
C36: 0000000000
C37: 0000000000
C38: 0000000000
C39: 0000000000
C40: 0000000000
...

Sheet 1Fドア
A1: プレハブ名 | B1: 数値 | C1: リスト
A2: 東ドア | B2: 00001 | C2: {=LEFT(B2:B100 & "0000000000", 10)} -> 0000100000
A3: 西ドア | B3: 00002 | C3: 0000200000 | M3: なし
A4: 南ドア | B4: 00003 | C4: 0000300000 | M4: 東ドア（仮）
A5: 北ドア | B5: 00004 | C5: 0000400000 | M5: 東ドア
A6: 東ドア＋南ドア | B6: 00005 | C6: 0000500000 | J6: なし | O6: 南ドア | P6: 南ドア（仮） | AB6: 南ドア | AC6: 南ドア（仮） | AD6: 南ドア | AE6: 南ドア（仮）
A7: 東ドア＋北ドア | B7: 00006 | C7: 0000600000 | J7: 東ドア（仮）
A8: 西ドア＋南ドア | B8: 00007 | C8: 0000700000 | J8: 東ドア | O8: 南ドア | P8: 南ドア（仮） | Z8: 南ドア | AA8: 南ドア（仮） | AB8: 南ドア（仮）
A9: 西ドア＋北ドア | B9: 00008 | C9: 0000800000 | J9: 東ドア（仮） | AF9: 東ドア（仮）
A10: 東ドア（仮） | C10: 0000000000 | J10: 東ドア | AF10: 東ドア
A11: 南ドア（仮） | C11: 0000000000 | G11: 北ドア（仮） | H11: 北ドア | M11: なし | N11: なし | AH11: 北ドア（仮） | AI11: 北ドア | AP11: ドアの置き方は
A12: 西ドア（仮） | C12: 0000000000 | N12: 東ドア（仮） | AB12: 東ドア（仮） | AP12: 例 | AQ12: 東のドアを置きたいとき
A13: 北ドア（仮） | C13: 0000000000 | N13: 東ドア | AB13: 東ドア | AR13: 東→
A14: 東ドア＋南ドア（仮） | C14: 0000000000 | AS14: なし →
A15: 東ドア＋北ドア（仮） | C15: 0000000000 | AS15: 東ドア→
A16: 西ドア＋南ドア（仮） | C16: 0000000000
A17: 西ドア＋北ドア（仮） | C17: 0000000000 | AP17: こんな感じで片方はプレハブを置くもう
C18: 0000000000 | AP18: 片方は何も置かない配置にする。
C19: 0000000000
C20: 0000000000 | AP20: ※注意
C21: 0000000000 | AP21: 東は下が東ドアになるように置く
C22: 0000000000 | AP22: 西は上が西ドアになるように置く
C23: 0000000000 | AP23: 南は左が南ドアになるように置く
C24: 0000000000 | AP24: 北は右が北ドアになるように置く
C25: 0000000000 | AP25: 例のなしのところは分かりにくいため
C26: 0000000000 | AP26: それぞれの（仮）をおいてください。
C27: 0000000000
C28: 0000000000
C29: 0000000000
C30: 0000000000
C31: 0000000000
C32: 0000000000
C33: 0000000000
C34: 0000000000
C35: 0000000000
C36: 0000000000
C37: 0000000000
C38: 0000000000
... C100: 0000000000

Sheet 1F窓
A1: プレハブ名 | B1: 数値 | C1: リスト
A2: 東窓 | B2: 0000001 | C2: {=LEFT(B2:B10 & "0000000000", 10)} -> 0000001000 | F2: なし | G2: なし | H2: なし | I2: なし | J2: なし | K2: なし | L2: なし | M2: なし | N2: なし | O2: なし | P2: なし | Q2: なし | R2: なし | S2: なし | T2: なし | U2: なし | V2: なし | W2: なし | X2: なし | Y2: なし | Z2: なし | AA2: なし | AB2: なし | AC2: なし | AD2: なし | AE2: なし | AF2: なし | AG2: なし | AH2: なし | AI2: なし | AJ2: なし | AK2: なし | AL2: なし | AM2: なし | AN2: なし | AO2: なし | AR2: 北
A3: 西窓 | B3: 0000002 | C3: 0000002000 | F3: なし | G3: なし | H3: なし | I3: なし | J3: なし | K3: なし | L3: なし | M3: なし | N3: なし | O3: なし | P3: なし | Q3: なし | R3: なし | S3: なし | T3: なし | U3: なし | V3: なし | W3: なし | X3: なし | Y3: なし | Z3: なし | AA3: なし | AB3: なし | AC3: なし | AD3: なし | AE3: なし | AF3: なし | AG3: なし | AH3: なし | AI3: なし | AJ3: なし | AK3: なし | AL3: なし | AM3: なし | AN3: なし | AO3: なし
A4: 南窓 | B4: 0000003 | C4: 0000003000 | F4: なし | G4: なし | H4: なし | I4: なし | J4: なし | K4: なし | L4: なし | M4: なし | N4: なし | O4: なし | P4: なし | Q4: なし | R4: なし | S4: なし | T4: なし | U4: なし | V4: なし | W4: なし | X4: なし | Y4: なし | Z4: なし | AA4: なし | AB4: なし | AC4: なし | AD4: なし | AE4: なし | AF4: なし | AG4: なし | AH4: なし | AI4: なし | AJ4: なし | AK4: なし | AL4: なし | AM4: なし | AN4: なし | AO4: なし
A5: 北窓 | B5: 0000004 | C5: 0000004000 | F5: なし | G5: なし | H5: なし | I5: なし | J5: なし | K5: なし | L5: なし | M5: なし | N5: なし | O5: なし | P5: なし | Q5: なし | R5: なし | S5: なし | T5: なし | U5: なし | V5: なし | W5: なし | X5: なし | Y5: なし | Z5: なし | AA5: なし | AB5: なし | AC5: なし | AD5: なし | AE5: なし | AF5: なし | AG5: なし | AH5: なし | AI5: なし | AJ5: なし | AK5: なし | AL5: なし | AM5: なし | AN5: なし | AO5: なし
A6: 東窓＋南窓 | B6: 0000005 | C6: 0000005000 | F6: なし | G6: なし | H6: なし | I6: なし | J6: なし | K6: なし | L6: なし | M6: なし | N6: なし | O6: なし | P6: なし | Q6: なし | R6: なし | S6: なし | T6: なし | U6: なし | V6: なし | W6: なし | X6: なし | Y6: なし | Z6: なし | AA6: なし | AB6: なし | AC6: なし | AD6: なし | AE6: なし | AF6: なし | AG6: なし | AH6: なし | AI6: なし | AJ6: なし | AK6: なし | AL6: なし | AM6: なし | AN6: なし | AO6: なし | AP6: 西 | AT6: 東
A7: 東窓＋北窓 | B7: 0000006 | C7: 0000006000 | F7: なし | G7: なし | H7: なし | I7: なし | J7: なし | K7: なし | L7: なし | M7: なし | N7: なし | O7: なし | P7: なし | Q7: なし | R7: なし | S7: なし | T7: なし | U7: なし | V7: なし | W7: なし | X7: なし | Y7: なし | Z7: なし | AA7: なし | AB7: なし | AC7: なし | AD7: なし | AE7: なし | AF7: なし | AG7: なし | AH7: なし | AI7: なし | AJ7: なし | AK7: なし | AL7: なし | AM7: なし | AN7: なし | AO7: なし
A8: 西窓＋南窓 | B8: 0000007 | C8: 0000007000 | F8: なし | G8: なし | H8: なし | I8: なし | J8: なし | K8: なし | L8: なし | M8: なし | N8: なし | O8: なし | P8: なし | Q8: なし | R8: なし | S8: なし | T8: なし | U8: なし | V8: なし | W8: なし | X8: なし | Y8: なし | Z8: なし | AA8: なし | AB8: なし | AC8: なし | AD8: なし | AE8: なし | AF8: なし | AG8: なし | AH8: なし | AI8: なし | AJ8: なし | AK8: なし | AL8: なし | AM8: なし | AN8: なし | AO8: なし
A9: 西窓＋北窓 | B9: 0000008 | C9: 0000008000 | F9: なし | G9: なし | H9: なし | I9: なし | J9: なし | K9: なし | L9: なし | M9: なし | N9: なし | O9: なし | P9: なし | Q9: なし | R9: なし | S9: なし | T9: なし | U9: なし | V9: なし | W9: なし | X9: なし | Y9: なし | Z9: なし | AA9: なし | AB9: なし | AC9: なし | AD9: なし | AE9: なし | AF9: なし | AG9: なし | AH9: なし | AI9: なし | AJ9: なし | AK9: なし | AL9: なし | AM9: なし | AN9: なし | AO9: なし
C10: 0000000000 | F10: なし | G10: なし | H10: なし | I10: なし | J10: なし | K10: なし | L10: なし | M10: なし | N10: なし | O10: なし | P10: なし | Q10: なし | R10: なし | S10: なし | T10: なし | U10: なし | V10: なし | W10: なし | X10: なし | Y10: なし | Z10: なし | AA10: なし | AB10: なし | AC10: なし | AD10: なし | AE10: なし | AF10: なし | AG10: なし | AH10: なし | AI10: なし | AJ10: なし | AK10: なし | AL10: なし | AM10: なし | AN10: なし | AO10: なし | AR10: 南
F11: なし | G11: なし | H11: なし | I11: なし | J11: なし | K11: なし | L11: なし | M11: なし | N11: なし | O11: なし | P11: なし | Q11: なし | R11: なし | S11: なし | T11: なし | U11: なし | V11: なし | W11: なし | X11: なし | Y11: なし | Z11: なし | AA11: なし | AB11: なし | AC11: なし | AD11: なし | AE11: なし | AF11: なし | AG11: なし | AH11: なし | AI11: なし | AJ11: なし | AK11: なし | AL11: なし | AM11: なし | AN11: なし | AO11: なし
F12: なし | G12: なし | H12: なし | I12: なし | J12: なし | K12: なし | L12: なし | M12: なし | N12: なし | O12: なし | P12: なし | Q12: なし | R12: なし | S12: なし | T12: なし | U12: なし | V12: なし | W12: なし | X12: なし | Y12: なし | Z12: なし | AA12: なし | AB12: なし | AC12: なし | AD12: なし | AE12: なし | AF12: なし | AG12: なし | AH12: なし | AI12: なし | AJ12: なし | AK12: なし | AL12: なし | AM12: なし | AN12: なし | AO12: なし
F13: なし | G13: なし | H13: なし | I13: なし | J13: なし | K13: なし | L13: なし | M13: なし | N13: なし | O13: なし | P13: なし | Q13: なし | R13: なし | S13: なし | T13: なし | U13: なし | V13: なし | W13: なし | X13: なし | Y13: なし | Z13: なし | AA13: なし | AB13: なし | AC13: なし | AD13: なし | AE13: なし | AF13: なし | AG13: なし | AH13: なし | AI13: なし | AJ13: なし | AK13: なし | AL13: なし | AM13: なし | AN13: なし | AO13: なし
F14: なし | G14: なし | H14: なし | I14: なし | J14: なし | K14: なし | L14: なし | M14: なし | N14: なし | O14: なし | P14: なし | Q14: なし | R14: なし | S14: なし | T14: なし | U14: なし | V14: なし | W14: なし | X14: なし | Y14: なし | Z14: なし | AA14: なし | AB14: なし | AC14: なし | AD14: なし | AE14: なし | AF14: なし | AG14: なし | AH14: なし | AI14: なし | AJ14: なし | AK14: なし | AL14: なし | AM14: なし | AN14: なし | AO14: なし
F15: なし | G15: なし | H15: なし | I15: なし | J15: なし | K15: なし | L15: なし | M15: なし | N15: なし | O15: なし | P15: なし | Q15: なし | R15: なし | S15: なし | T15: なし | U15: なし | V15: なし | W15: なし | X15: なし | Y15: なし | Z15: なし | AA15: なし | AB15: なし | AC15: なし | AD15: なし | AE15: なし | AF15: なし | AG15: なし | AH15: なし | AI15: なし | AJ15: なし | AK15: なし | AL15: なし | AM15: なし | AN15: なし | AO15: なし
F16: なし | G16: なし | H16: なし | I16: なし | J16: なし | K16: なし | L16: なし | M16: なし | N16: なし | O16: なし | P16: なし | Q16: なし | R16: なし | S16: なし | T16: なし | U16: なし | V16: なし | W16: なし | X16: なし | Y16: なし | Z16: なし | AA16: なし | AB16: なし | AC16: なし | AD16: なし | AE16: なし | AF16: なし | AG16: なし | AH16: なし | AI16: なし | AJ16: なし | AK16: なし | AL16: なし | AM16: なし | AN16: なし | AO16: なし
F17: なし | G17: なし | H17: なし | I17: なし | J17: なし | K17: なし | L17: なし | M17: なし | N17: なし | O17: なし | P17: なし | Q17: なし | R17: なし | S17: なし | T17: なし | U17: なし | V17: なし | W17: なし | X17: なし | Y17: なし | Z17: なし | AA17: なし | AB17: なし | AC17: なし | AD17: なし | AE17: なし | AF17: なし | AG17: なし | AH17: なし | AI17: なし | AJ17: なし | AK17: なし | AL17: なし | AM17: なし | AN17: なし | AO17: なし
F18: なし | G18: なし | H18: なし | I18: なし | J18: なし | K18: なし | L18: なし | M18: なし | N18: なし | O18: なし | P18: なし | Q18: なし | R18: なし | S18: なし | T18: なし | U18: なし | V18: なし | W18: なし | X18: なし | Y18: なし | Z18: なし | AA18: なし | AB18: なし | AC18: なし | AD18: なし | AE18: なし | AF18: なし | AG18: なし | AH18: なし | AI18: なし | AJ18: なし | AK18: なし | AL18: なし | AM18: なし | AN18: なし | AO18: なし
F19: なし | G19: なし | H19: なし | I19: なし | J19: なし | K19: なし | L19: なし | M19: なし | N19: なし | O19: なし | P19: なし | Q19: なし | R19: なし | S19: なし | T19: なし | U19: なし | V19: なし | W19: なし | X19: なし | Y19: なし | Z19: なし | AA19: なし | AB19: なし | AC19: なし | AD19: なし | AE19: なし | AF19: なし | AG19: なし | AH19: なし | AI19: なし | AJ19: なし | AK19: なし | AL19: なし | AM19: なし | AN19: なし | AO19: なし
F20: なし | G20: なし | H20: なし | I20: なし | J20: なし | K20: なし | L20: なし | M20: なし | N20: なし | O20: なし | P20: なし | Q20: なし | R20: なし | S20: なし | T20: なし | U20: なし | V20: なし | W20: なし | X20: なし | Y20: なし | Z20: なし | AA20: なし | AB20: なし | AC20: なし | AD20: なし | AE20: なし | AF20: なし | AG20: なし | AH20: なし | AI20: なし | AJ20: なし | AK20: なし | AL20: なし | AM20: なし | AN20: なし | AO20: なし
F21: なし | G21: なし | H21: なし | I21: なし | J21: なし | K21: なし | L21: なし | M21: なし | N21: なし | O21: なし | P21: なし | Q21: なし | R21: なし | S21: なし | T21: なし | U21: なし | V21: なし | W21: なし | X21: なし | Y21: なし | Z21: なし | AA21: なし | AB21: なし | AC21: なし | AD21: なし | AE21: なし | AF21: なし | AG21: なし | AH21: なし | AI21: なし | AJ21: なし | AK21: なし | AL21: なし | AM21: なし | AN21: なし | AO21: なし
F22: なし | G22: なし | H22: なし | I22: なし | J22: なし | K22: なし | L22: なし | M22: なし | N22: なし | O22: なし | P22: なし | Q22: なし | R22: なし | S22: なし | T22: なし | U22: なし | V22: なし | W22: なし | X22: なし | Y22: なし | Z22: なし | AA22: なし | AB22: なし | AC22: なし | AD22: なし | AE22: なし | AF22: なし | AG22: なし | AH22: なし | AI22: なし | AJ22: なし | AK22: なし | AL22: なし | AM22: なし | AN22: なし | AO22: なし
... F30: なし | G30: なし | H30: なし | I30: なし | J30: なし | K30: なし | L30: なし | M30: なし | N30: なし | O30: なし | P30: なし | Q30: なし | R30: なし | S30: なし | T30: なし | U30: なし | V30: なし | W30: なし | X30: なし | Y30: なし | Z30: なし | AA30: なし | AB30: なし | AC30: なし | AD30: なし | AE30: なし | AF30: なし | AG30: なし | AH30: なし | AI30: なし | AJ30: なし | AK30: なし | AL30: なし | AM30: なし | AN30: なし | AO30: なし

Sheet 1F家具
A1: プレハブ名 | B1: 数値 | C1: リスト
A2: プレイヤー | B2: 0000000001 | C2: {=LEFT(B2:B100 & "0000000000", 10)} -> 0000000001
C3: 0000000000
C4: 0000000000
C5: 0000000000
C6: 0000000000
C7: 0000000000
C8: 0000000000
C9: 0000000000
C10: 0000000000
C11: 0000000000
C12: 0000000000
C13: 0000000000 | V13: プレイヤー
C14: 0000000000
C15: 0000000000
C16: 0000000000
C17: 0000000000
C18: 0000000000
C19: 0000000000
C20: 0000000000
C21: 0000000000
C22: 0000000000
C23: 0000000000
C24: 0000000000
C25: 0000000000
... C100: 0000000000

Sheet CSV_Output
A1: =(IFERROR(VLOOKUP('1F床'!F2,'1F床'!$A:$C,3,FALSE),0)+IFERROR(VLOOKUP('1F壁'!F2,'1F壁'!$A:$C,3,FALSE),0)+IFERROR(VLOOKUP('1Fドア'!F2,'1Fドア'!$A:$C,3,FALSE),0)+IFERROR(VLOOKUP('1F窓'!F2,'1F窓'!$A:$C,3,FALSE),0)+IFERROR(VLOOKUP('1F家具'!F2,'1F家具'!$A:$C,3,FALSE),0))&"_"&(IFERROR(VLOOKUP('2F床'!F2,'2F床'!$A:$C,3,FALSE),0)+IFERROR(VLOOKUP('2F壁'!F2,'2F壁'!$A:$C,3,FALSE),0)+IFERROR(VLOOKUP('2Fドア'!F2,'2Fドア'!$A:$C,3,FALSE),0)+IFERROR(VLOOKUP('2F窓'!F2,'2F窓'!$A:$C,3,FALSE),0)+IFERROR(VLOOKUP('2F家具'!F2,'2F家具'!$A:$C,3,FALSE),0)) -> 1000000000_1000000000 | B1: =(IFERROR(VLOOKUP('1F床'!G2,'1F床'!$A:$C,3,FALSE),0)+IFERROR(VLOOKUP('1F壁'!G2,'1F壁'!$A:$C,3,FALSE),0)+IFERROR(VLOOKUP('1Fドア'!G2,'1Fドア'!$A:$C,3,FALSE),0)+IFERROR(VLOOKUP('1F窓'!G2,'1F窓'!$A:$C,3,FALSE),0)+IFERROR(VLOOKUP('1F家具'!G2,'1F家具'!$A:$C,3,FALSE),0))&"_"&(IFERROR(VLOOKUP('2F床'!G2,'2F床'!$A:$C,3,FALSE),0)+IFERROR(VLOOKUP('2F壁'!G2,'2F壁'!$A:$C,3,FALSE),0)+IFERROR(VLOOKUP('2Fドア'!G2,'2Fドア'!$A:$C,3,FALSE),0)+IFERROR(VLOOKUP('2F窓'!G2,'2F窓'!$A:$C,3,FALSE),0)+IFERROR(VLOOKUP('2F家具'!G2,'2F家具'!$A:$C,3,FALSE),0)) -> 1000000000_1000000000 | C1: =(IFERROR(VLOOKUP('1F床'!H2,'1F床'!$A:$C,3,FALSE),0)+IFERROR(VLOOKUP('1F壁'!H2,'1F壁'!$A:$C,3,FALSE),0)+IFERROR(VLOOKUP('1Fドア'!H2,'1Fドア'!$A:$C,3,FALSE),0)+IFERROR(VLOOKUP('1F窓'!H2,'1F窓'!$A:$C,3,FALSE),0)+IFERROR(VLOOKUP('1F家具'!H2,'1F家具'!$A:$C,3,FALSE),0))&"_"&(IFERROR(VLOOKUP('2F床'!H2,'2F床'!$A:$C,3,FALSE),0)+IFERROR(VLOOKUP('2F壁'!H2,'2F壁'!$A:$C,3,FALSE),0)+IFERROR(VLOOKUP('2Fドア'!H2,'2Fドア'!$A:$C,3,FALSE),0)+IFERROR(VLOOKUP('2F窓'!H2,'2F窓'!$A:$C,3,FALSE),0)+IFERROR(VLOOKUP('2F家具'!H2,'2F家具'!$A:$C,3,FALSE),0)) -> 1000000000_1000000000 | D1: =(IFERROR(VLOOKUP('1F床'!I2,'1F床'!$A:$C,3,FALSE),0)+IFERROR(VLOOKUP('1F壁'!I2,'1F壁'!$A:$C,3,FALSE),0)+IFERROR(VLOOKUP('1Fドア'!I2,'1Fドア'!$A:$C,3,FALSE),0)+IFERROR(VLOOKUP('1F窓'!I2,'1F窓'!$A:$C,3,FALSE),0)+IFERROR(VLOOKUP('1F家具'!I2,'1F家具'!$A:$C,3,FALSE),0))&"_"&(IFERROR(VLOOKUP('2F床'!I2,'2F床'!$A:$C,3,FALSE),0)+IFERROR(VLOOKUP('2F壁'!I2,'2F壁'!$A:$C,3,FALSE),0)+IFERROR(VLOOKUP('2Fドア'!I2,'2Fドア'!$A:$C,3,FALSE),0)+IFERROR(VLOOKUP('2F窓'!I2,'2F窓'!$A:$C,3,FALSE),0)+IFERROR(VLOOKUP('2F家具'!I2,'2F家具'!$A:$C,3,FALSE),0)) -> 1000000000_1000000000 | E1: =(IFERROR(VLOOKUP('1F床'!J2,'1F床'!$A:$C,3,FALSE),0)+IFERROR(VLOOKUP('1F壁'!J2,'1F壁'!$A:$C,3,FALSE),0)+IFERROR(VLOOKUP('1Fドア'!J2,'1Fドア'!$A:$C,3,FALSE),0)+IFERROR(VLOOKUP('1F窓'!J2,'1F窓'!$A:$C,3,FALSE),0)+IFERROR(VLOOKUP('1F家具'!J2,'1F家具'!$A:$C,3,FALSE),0))&"_"&(IFERROR(VLOOKUP('2F床'!J2,'2F床'!$A:$C,3,FALSE),0)+IFERROR(VLOOKUP('2F壁'!J2,'2F壁'!$A:$C,3,FALSE),0)+IFERROR(VLOOKUP('2Fドア'!J2,'2Fドア'!$A:$C,3,FALSE),0)+IFERROR(VLOOKUP('2F窓'!J2,'2F窓'!$A:$C,3,FALSE),0)+IFERROR(VLOOKUP('2F家具'!J2,'2F家具'!$A:$C,3,FALSE),0)) -> 1000000000_1000000000 | F1: =(IFERROR(VLOOKUP('1F床'!K2,'1F床'!$A:$C,3,FALSE),0)+IFERROR(VLOOKUP('1F壁'!K2,'1F壁'!$A:$C,3,FALSE),0)+IFERROR(VLOOKUP('1Fドア'!K2,'1Fドア'!$A:$C,3,FALSE),0)+IFERROR(VLOOKUP('1F窓'!K2,'1F窓'!$A:$C,3,FALSE),0)+IFERROR(VLOOKUP('1F家具'!K2,'1F家具'!$A:$C,3,FALSE),0))&"_"&(IFERROR(VLOOKUP('2F床'!K2,'2F床'!$A:$C,3,FALSE),0)+IFERROR(VLOOKUP('2F壁'!K2,'2F壁'!$A:$C,3,FALSE),0)+IFERROR(VLOOKUP('2Fドア'!K2,'2Fドア'!$A:$C,3,FALSE),0)+IFERROR(VLOOKUP('2F窓'!K2,'2F窓'!$A:$C,3,FALSE),0)+IFERROR(VLOOKUP('2F家具'!K2,'2F家具'!$A:$C,3,FALSE),0)) -> 1000000000_1000000000 | G1: =(IFERROR(VLOOKUP('1F床'!L2,'1F床'!$A:$C,3,FALSE),0)+IFERROR(VLOOKUP('1F壁'!L2,'1F壁'!$A:$C,3,FALSE),0)+IFERROR(VLOOKUP('1Fドア'!L2,'1Fドア'!$A:$C,3,FALSE),0)+IFERROR(VLOOKUP('1F窓'!L2,'1F窓'!$A:$C,3,FALSE),0)+IFERROR(VLOOKUP('1F家具'!L2,'1F家具'!$A:$C,3,FALSE),0))&"_"&(IFERROR(VLOOKUP('2F床'!L2,'2F床'!$A:$C,3,FALSE),0)+IFERROR(VLOOKUP('2F壁'!L2,'2F壁'!$A:$C,3,FALSE),0)+IFERROR(VLOOKUP('2Fドア'!L2,'2Fドア'!$A:$C,3,FALSE),0)+IFERROR(VLOOKUP('2F窓'!L2,'2F窓'!$A:$C,3,FALSE),0)+IFERROR(VLOOKUP('2F家具'!L2,'2F家具'!$A:$C,3,FALSE),0)) -> 1000000000_1000000000 | H1: =(IFERROR(VLOOKUP('1F床'!M2,'1F床'!$A:$C,3,FALSE),0)+IFERROR(VLOOKUP('1F壁'!M2,'1F壁'!$A:$C,3,FALSE),0)+IFERROR(VLOOKUP('1Fドア'!M2,'1Fドア'!$A:$C,3,FALSE),0)+IFERROR(VLOOKUP('1F窓'!M2,'1F窓'!$A:$C,3,FALSE),0)+IFERROR(VLOOKUP('1F家具'!M2,'1F家具'!$A:$C,3,FALSE),0))&"_"&(IFERROR(VLOOKUP('2F床'!M2,'2F床'!$A:$C,3,FALSE),0)+IFERROR(VLOOKUP('2F壁'!M2,'2F壁'!$A:$C,3,FALSE),0)+IFERROR(VLOOKUP('2Fドア'!M2,'2Fドア'!$A:$C,3,FALSE),0)+IFERROR(VLOOKUP('2F窓'!M2,'2F窓'!$A:$C,3,FALSE),0)+IFERROR(VLOOKUP('2F家具'!M2,'2F家具'!$A:$C,3,FALSE),0)) -> 1000000000_1000000000 | ... AK1: =(IFERROR(VLOOKUP('1F床'!AP2,'1F床'!$A:$C,3,FALSE),0)+IFERROR(VLOOKUP('1F壁'!AP2,'1F壁'!$A:$C,3,FALSE),0)+IFERROR(VLOOKUP('1Fドア'!AP2,'1Fドア'!$A:$C,3,FALSE),0)+IFERROR(VLOOKUP('1F窓'!AP2,'1F窓'!$A:$C,3,FALSE),0)+IFERROR(VLOOKUP('1F家具'!AP2,'1F家具'!$A:$C,3,FALSE),0))&"_"&(IFERROR(VLOOKUP('2F床'!AP2,'2F床'!$A:$C,3,FALSE),0)+IFERROR(VLOOKUP('2F壁'!AP2,'2F壁'!$A:$C,3,FALSE),0)+IFERROR(VLOOKUP('2Fドア'!AP2,'2Fドア'!$A:$C,3,FALSE),0)+IFERROR(VLOOKUP('2F窓'!AP2,'2F窓'!$A:$C,3,FALSE),0)+IFERROR(VLOOKUP('2F家具'!AP2,'2F家具'!$A:$C,3,FALSE),0)) -> 0_0 | AL1: =(IFERROR(VLOOKUP('1F床'!AQ2,'1F床'!$A:$C,3,FALSE),0)+IFERROR(VLOOKUP('1F壁'!AQ2,'1F壁'!$A:$C,3,FALSE),0)+IFERROR(VLOOKUP('1Fドア'!#REF!,'1Fドア'!$A:$C,3,FALSE),0)+IFERROR(VLOOKUP('1F窓'!AQ2,'1F窓'!$A:$C,3,FALSE),0)+IFERROR(VLOOKUP('1F家具'!AQ2,'1F家具'!$A:$C,3,FALSE),0))&"_"&(IFERROR(VLOOKUP('2F床'!AQ2,'2F床'!$A:$C,3,FALSE),0)+IFERROR(VLOOKUP('2F壁'!AQ2,'2F壁'!$A:$C,3,FALSE),0)+IFERROR(VLOOKUP('2Fドア'!AQ2,'2Fドア'!$A:$C,3,FALSE),0)+IFERROR(VLOOKUP('2F窓'!AQ2,'2F窓'!$A:$C,3,FALSE),0)+IFERROR(VLOOKUP('2F家具'!AQ2,'2F家具'!$A:$C,3,FALSE),0)) -> 0_0 | AM1: =(IFERROR(VLOOKUP('1F床'!AR2,'1F床'!$A:$C,3,FALSE),0)+IFERROR(VLOOKUP('1F壁'!AR2,'1F壁'!$A:$C,3,FALSE),0)+IFERROR(VLOOKUP('1Fドア'!#REF!,'1Fドア'!$A:$C,3,FALSE),0)+IFERROR(VLOOKUP('1F窓'!AR2,'1F窓'!$A:$C,3,FALSE),0)+IFERROR(VLOOKUP('1F家具'!AR2,'1F家具'!$A:$C,3,FALSE),0))&"_"&(IFERROR(VLOOKUP('2F床'!AR2,'2F床'!$A:$C,3,FALSE),0)+IFERROR(VLOOKUP('2F壁'!AR2,'2F壁'!$A:$C,3,FALSE),0)+IFERROR(VLOOKUP('2Fドア'!AR2,'2Fドア'!$A:$C,3,FALSE),0)+IFERROR(VLOOKUP('2F窓'!AR2,'2F窓'!$A:$C,3,FALSE),0)+IFERROR(VLOOKUP('2F家具'!AR2,'2F家具'!$A:$C,3,FALSE),0)) -> 0_0 | AN1: =(IFERROR(VLOOKUP('1F床'!AS2,'1F床'!$A:$C,3,FALSE),0)+IFERROR(VLOOKUP('1F壁'!AS2,'1F壁'!$A:$C,3,FALSE),0)+IFERROR(VLOOKUP('1Fドア'!#REF!,'1Fドア'!$A:$C,3,FALSE),0)+IFERROR(VLOOKUP('1F窓'!AS2,'1F窓'!$A:$C,3,FALSE),0)+IFERROR(VLOOKUP('1F家具'!AS2,'1F家具'!$A:$C,3,FALSE),0))&"_"&(IFERROR(VLOOKUP('2F床'!AS2,'2F床'!$A:$C,3,FALSE),0)+IFERROR(VLOOKUP('2F壁'!AS2,'2F壁'!$A:$C,3,FALSE),0)+IFERROR(VLOOKUP('2Fドア'!AS2,'2Fドア'!$A:$C,3,FALSE),0)+IFERROR(VLOOKUP('2F窓'!AS2,'2F窓'!$A:$C,3,FALSE),0)+IFERROR(VLOOKUP('2F家具'!AS2,'2F家具'!$A:$C,3,FALSE),0)) -> 0_0
